Workbook

Sheet 012026
B1: 46023 | C1: 46054 | D1: 46082 | E1: 46113 | F1: 46143 | G1: 46174 | H1: 46204 | I1: 46235 | J1: 46266 | K1: 46296 | L1: 46327 | M1: 46357
A2: DETALLE CALCULO GANANCIAS 2026
A5: Tope cargas sociales Enero 2026 | B5: 3823373
A6: Tope cargas sociales Febrero 2026 | B6: 3932339.1
A7: SAC | C7: =B4*A4*0.17 -> 0
A16: Tope cargas sociales Marzo 2026 | B16: 4045590.5
A17: Tope cargas sociales Abril 2026 | B17: 3128545.7
A18: Tope cargas sociales Mayo 2026 | B18: 3245240.5
A19: Tope cargas sociales Junio 2026 | B19: 3335458.2 | C19: =B19/2 -> 1667729.1
A20: Tope cargas sociales Julio 2026 | B20: 3385490
A21: Tope cargas sociales AGOSTO 2026 | B21: 3440335 | C21: =B21/2 -> 1720167.5
A22: Tope cargas sociales SEPTIEMBRE 2026 | B22: 3505701.4
A23: Tope cargas sociales OCTUBRE 2026 | B23: 3571608.5
A24: Tope cargas sociales NOVIEMBRE 2026 | B24: 3645898 | G24: vac
A25: Tope cargas sociales DICIEMBRE 2026 | B25: 3731212 | C25: =B25/2 -> 1865606 | G25: =G28/7 -> 0
B26: 46023 | C26: 46054 | D26: 46082 | E26: 46113 | F26: 46143 | G26: 46174 | H26: 46204 | I26: 46235 | J26: 46266 | K26: 46296 | L26: 46327 | M26: 46357
A27: Sueldo bruto | B27: 3835388 | C27: =B27 -> 3835388 | D27: =C27 -> 3835388 | E27: =D27 -> 3835388 | F27: =E27 -> 3835388 | G27: =F27 -> 3835388 | H27: =G27 -> 3835388 | I27: =H27 -> 3835388 | J27: =I27 -> 3835388 | ... M27: =L27 -> 3835388 | N27: =SUM(B27:M27) -> 46024656
A28: Plus vacaciones | B28: 178984.77 | N28: =SUM(B28:M28) -> 178984.77
A29: SAC REAL | G29: =G27/2 -> 1917694 | M29: =M27/2 -> 1917694 | N29: =SUM(B29:M29) -> 3835388
A30: SAC Prorrateado | B30: =(B27)/12 -> 319615.67 | C30: =(C27)/12 -> 319615.67 | D30: =(D27)/12 -> 319615.67 | E30: =(E27)/12 -> 319615.67 | F30: =(F27)/12 -> 319615.67 | H30: =(H27)/12 -> 319615.67 | I30: =(I27)/12 -> 319615.67 | J30: =(J27)/12 -> 319615.67 | K30: =(K27)/12 -> 319615.67 | L30: =(L27)/12 -> 319615.67 | N30: =SUM(B30:M30) -> 3196156.7
B31: =+B27+B30 -> 4155003.7 | C31: =+C27+C30 -> 4155003.7 | D31: =+D27+D30 -> 4155003.7 | E31: =SUM(E27:E30) -> 4155003.7 | F31: =+F27+F30 -> 4155003.7 | G31: =SUM(G27:G30) -> 5753082 | H31: =+H27+H30 -> 4155003.7 | I31: =SUM(I27:I30) -> 4155003.7 | J31: =SUM(J27:J30) -> 4155003.7 | K31: =+K27+K30 -> 4155003.7 | L31: =+L27+L30 -> 4155003.7 | M31: =SUM(M27:M30) -> 5753082 | N31: =SUM(B31:M31) -> 53056201
A32: art 26 gravado en su totalidad | N32: =SUM(B32:M32) -> 0
A33: BONO | N33: =SUM(B33:M33) -> 0
A37: Sub Total Ganancia Bruta | B37: =B33+B27 -> 3835388 | C37: =C33+C27 -> 3835388 | D37: =D33+D27 -> 3835388 | E37: =E33+E27 -> 3835388 | F37: =F33+F27 -> 3835388 | G37: =G33+G27 -> 3835388 | H37: =H33+H27 -> 3835388 | I37: =I33+I27 -> 3835388 | ... M37: =M33+M27 -> 3835388 | N37: =SUM(B37:M37) -> 46024656
N38: =SUM(B38:M38) -> 0
A39: Jubilac. | B39: =-B5*11% -> -420571.02 | C39: =-C27*11% -> -421892.68 | D39: =-B16*11% -> -445014.95 | E39: =-B17*11% -> -344140.03 | F39: =-B18*11% -> -356976.45 | G39: =-B19*0.11 -> -366900.4 | H39: =-B20*11% -> -372403.91 | I39: =-B21*0.11 -> -378436.85 | J39: =-B22*0.11 -> -385627.15 | K39: =-B23*0.11 -> -392876.94 | L39: =-B24*0.11 -> -401048.78 | M39: =-B25*0.11 -> -410433.32 | N39: =SUM(B39:M39) -> -4696322.5
A40: Ley 19032 | B40: =-B5*3% -> -114701.19 | C40: =-C27*3% -> -115061.64 | D40: =-B16*3% -> -121367.71 | E40: =-B17*3% -> -93856.372 | F40: =-B18*3% -> -97357.215 | G40: =-B19*0.03 -> -100063.75 | H40: =-B20*3% -> -101564.7 | I40: =-B21*0.03 -> -103210.05 | J40: =-B22*0.03 -> -105171.04 | K40: =-B23*0.03 -> -107148.26 | L40: =-B24*0.03 -> -109376.94 | M40: =-B25*0.03 -> -111936.36 | N40: =SUM(B40:M40) -> -1280815.2
A41: Obra social | B41: =-B5*3% -> -114701.19 | C41: =C40 -> -115061.64 | D41: =-B16*3% -> -121367.71 | E41: =-B17*3% -> -93856.372 | F41: =-B18*3% -> -97357.215 | G41: =G40 -> -100063.75 | H41: =-B20*3% -> -101564.7 | I41: =-B21*0.03 -> -103210.05 | J41: =J40 -> -105171.04 | K41: =K40 -> -107148.26 | L41: =L40 -> -109376.94 | M41: =M40 -> -111936.36 | N41: =SUM(B41:M41) -> -1280815.2
N42: =SUM(B42:M42) -> 0
A43: Total Descuentos | B43: =SUM(B39:B42) -> -649973.4 | C43: =SUM(C39:C42) -> -652015.96 | D43: =SUM(D39:D42) -> -687750.38 | E43: =SUM(E39:E42) -> -531852.77 | F43: =SUM(F39:F42) -> -551690.88 | G43: =SUM(G39:G42) -> -567027.89 | H43: =SUM(H39:H42) -> -575533.31 | I43: =SUM(I39:I42) -> -584856.95 | ... M43: =SUM(M39:M42) -> -634306.04 | N43: =SUM(B43:M43) -> -7257952.9
N44: =SUM(B44:M44) -> 0
A45: Ingresos gravados (menos SAC) | B45: =B27++B33 -> 3835388 | C45: =C27+B45 -> 7670776 | D45: =D27+C45 -> 11506164 | E45: =E27+D45 -> 15341552 | F45: =F27+E45 -> 19176940 | G45: =G27+F45 -> 23012328 | H45: =H27+G45 -> 26847716 | I45: =I27+H45 -> 30683104 | J45: =J27+I45 -> 34518492 | ... M45: =M27+L45 -> 46024656 | N45: =SUM(B45:M45) -> 299160264
N46: =SUM(B46:M46) -> 0
A47: Prorrateo vacaciones | B47: =+B28/12 -> 14915.398 | C47: =$B$47+B47 -> 29830.796 | D47: =$B$47+C47 -> 44746.193 | E47: =$B$47+D47 -> 59661.591 | F47: =$B$47+E47 -> 74576.989 | G47: =$B$47+F47 -> 89492.387 | H47: =$B$47+G47 -> 104407.78 | I47: =$B$47+H47 -> 119323.18 | J47: =$B$47+I47 -> 134238.58 | ... M47: =$B$47+L47 -> 178984.77 | N47: =M47 -> 178984.77
A48: Descuentos | N48: =SUM(B48:M48) -> 0
B49: =SUM(B47:B48) -> 14915.398 | C49: =SUM(C47:C48) -> 29830.796 | D49: =SUM(D47:D48) -> 44746.193 | E49: =SUM(E47:E48) -> 59661.591 | F49: =SUM(F47:F48) -> 74576.989 | G49: =SUM(G47:G48) -> 89492.387 | H49: =SUM(H47:H48) -> 104407.78 | I49: =SUM(I47:I48) -> 119323.18 | ... M49: =SUM(M47:M48) -> 178984.77 | N49: =SUM(B49:M49) -> 1163401
A52: Ingresos Gravados Acumulados SUELDO MAS VACACIONES | B52: =B45+B47 -> 3850303.4 | C52: =C45+C47 -> 7700606.8 | D52: =D45+D47 -> 11550910 | E52: =E45+E47 -> 15401214 | F52: =F45+F47 -> 19251517 | G52: =G45+G47 -> 23101820 | H52: =H45+H47 -> 26952124 | I52: =I45+I47 -> 30802427 | ... M52: =M45+M47 -> 46203641 | N52: =M52 -> 46203641
A54: Ajuste al neto SAC | B54: =-B30+B61 -> -265451.22 | C54: =-C30+C61 -> -265281 | D54: =-D30+D61 -> -262303.14 | E54: =-E30+E61 -> -275294.6 | F54: =-F30+F61 -> -273641.43 | G54: =C19*0.17+-G29-SUM(B54:F54) -> -292208.67 | H54: =-H30+H61 -> -271654.56 | I54: =-I30+I61 -> -270877.59 | J54: =-J30+J61 -> -269951.56 | K54: =-K30+K61 -> -269017.88 | L54: =-L30+L61 -> -267965.45 | M54: =C25*0.17+-M29-SUM(H54:L54) -> -251073.95 | N54: SAC DIC
A55: Ajuste al neto SAC ACUM | B55: =B54 -> -265451.22 | C55: =C54+B55 -> -530732.22 | D55: =D54+C55 -> -793035.36 | E55: =E54+D55 -> -1068330 | F55: =F54+E55 -> -1341971.4 | G55: =G54+F55 -> -1634180.1 | H55: =H54+G55 -> -1905834.6 | I55: =I54+H55 -> -2176712.2 | J55: =J54+I55 -> -2446663.8 | ... M55: =M54+L55 -> -3234721 | N55: =-#REF!+#REF! -> #REF!
A56: ajuste neto sac 1 a 5 2024 según rg 5531 art 1 k
...

Sheet Escalas
A3: GANANCIA NETA ACUMULADA | C3: PAGARAN
A4: MAS DE $ | B4: A $ | C4: $ | D4: MAS EL % | E4: S/EXCEDENTE DE
A5: 0 | B5: 1520371.7 | C5: 0 | D5: 5 | E5: 0
A6: 1520371.7 | B6: 3040743.3 | C6: 76018.58 | D6: 9 | E6: 1520371.7
A7: 3040743.3 | B7: 4561115 | C7: 212852.03 | D7: 12 | E7: 3040743.3
A8: 4561115 | B8: 6841672.5 | C8: 395296.63 | D8: 15 | E8: 4561115
A9: 6841672.5 | B9: 13683345 | C9: 737380.26 | D9: 19 | E9: 6841672.5
A10: 13683345 | B10: 20525018 | C10: 2037298 | D10: 23 | E10: 13683345
A11: 20525018 | B11: 30787526 | C11: 3610882.7 | D11: 27 | E11: 20525018
A12: 30787526 | B12: 46181290 | C12: 6381760.1 | D12: 31 | E12: 30787526
A13: 46181290 | B13: en adelante | C13: 11153827 | D13: 35 | E13: 46181290
A17: 20
A18: 1 | B18: 1 | C18: 1 | D18: 1 | E18: 1
A19: 0 | B19: 166669.17 | C19: 0 | D19: 0.05 | E19: 0
A20: 166669.17 | B20: 333338.35 | C20: 8333.46 | D20: 0.09 | E20: 166669.17
A21: 333338.35 | B21: 500007.52 | C21: 23333.68 | D21: 0.12 | E21: 333338.35
A22: 500007.52 | B22: 750011.28 | C22: 43333.99 | D22: 0.15 | E22: 500007.52
A23: 750011.28 | B23: 1500022.6 | C23: 80834.55 | D23: 0.19 | E23: 750011.28
A24: 1500022.6 | B24: 2250033.9 | C24: 223336.69 | D24: 0.23 | E24: 1500022.6
A25: 2250033.9 | B25: 3375050.8 | C25: 395839.29 | D25: 0.27 | E25: 2250033.9
A26: 3375050.8 | B26: 5062576.2 | C26: 699593.86 | D26: 0.31 | E26: 3375050.8
A27: 5062576.2 | B27: en adelante | C27: 1222726.7 | D27: 0.35 | E27: 5062576.2
A28: =+A18+1 -> 2 | B28: =+B18+1 -> 2 | C28: =+C18+1 -> 2 | E28: =+E18+1 -> 2
A29: 0 | B29: 333338.35 | C29: 0 | D29: 0.05 | E29: 0
A30: 333338.35 | B30: 666676.69 | C30: 16666.92 | D30: 0.09 | E30: 333338.35
A31: 666676.69 | B31: 1000015 | C31: 46667.37 | D31: 0.12 | E31: 666676.69
A32: 1000015 | B32: 1500022.6 | C32: 86667.97 | D32: 0.15 | E32: 1000015
A33: 1500022.6 | B33: 3000045.1 | C33: 161669.1 | D33: 0.19 | E33: 1500022.6
A34: 3000045.1 | B34: 4500067.7 | C34: 446673.39 | D34: 0.23 | E34: 3000045.1
A35: 4500067.7 | B35: 6750101.5 | C35: 791678.58 | D35: 0.27 | E35: 4500067.7
A36: 6750101.5 | B36: 10125152 | C36: 1399187.7 | D36: 0.31 | E36: 6750101.5
A37: 10125152 | B37: en adelante | C37: 2445453.5 | D37: 0.35 | E37: 10125152
A38: =+A28+1 -> 3 | B38: =+B28+1 -> 3 | C38: =+C28+1 -> 3 | E38: =+E28+1 -> 3
A39: 0 | B39: 500007.52 | C39: 0 | D39: 0.05 | E39: 0
A40: 500007.52 | B40: 1000015 | C40: 25000.38 | D40: 0.09 | E40: 500007.52
A41: 1000015 | B41: 1500022.6 | C41: 70001.05 | D41: 0.12 | E41: 1000015
A42: 1500022.6 | B42: 2250033.9 | C42: 130001.96 | D42: 0.15 | E42: 1500022.6
A43: 2250033.9 | B43: 4500067.7 | C43: 242503.65 | D43: 0.19 | E43: 2250033.9
A44: 4500067.7 | B44: 6750101.5 | C44: 670010.08 | D44: 0.23 | E44: 4500067.7
A45: 6750101.5 | B45: 10125152 | C45: 1187517.9 | D45: 0.27 | E45: 6750101.5
...

Sheet Tablas 
A1: Tabla de Deducciones | N1: https://www.afip.gob.ar/gananciasYBienes/ganancias/personas-humanas-sucesiones-indivisas/deducciones/documentos/Deducciones-personales-art-30-enero-junio-2025.pdf
B2: 1 | C2: 2 | D2: 3 | E2: 4 | F2: 5 | G2: 6 | H2: 7 | I2: 8 | J2: 9 | K2: 10 | L2: 11 | M2: 12 | N2: 13
A3: Ganancia No Imponible | B3: =+$N$3/12*B2 -> 429316.88 | C3: =+$N$3/12*C2 -> 858633.75 | D3: =+$N$3/12*D2 -> 1287950.6 | E3: =+$N$3/12*E2 -> 1717267.5 | F3: =+$N$3/12*F2 -> 2146584.4 | G3: =+$N$3/12*G2 -> 2575901.2 | H3: =+$N$3/12*H2 -> 3005218.1 | I3: =+$N$3/12*I2 -> 3434535 | ... M3: =+$N$3/12*M2 -> 5151802.5 | N3: 5151802.5 | O3: 5151802.5 | P3: GNI
A4: Deducción Especial | B4: =+$N$4/12*B2 -> 2060721 | C4: =+$N$4/12*C2 -> 4121442 | D4: =+$N$4/12*D2 -> 6182163 | E4: =+$N$4/12*E2 -> 8242884 | F4: =+$N$4/12*F2 -> 10303605 | G4: =+$N$4/12*G2 -> 12364326 | H4: =+$N$4/12*H2 -> 14425047 | I4: =+$N$4/12*I2 -> 16485768 | ... M4: =+$N$4/12*M2 -> 24728652 | N4: 24728652 | O4: 24728652 | P4: Deducción especial
A5: Cónyuge | B5: =+$N$5/12*B2 -> 404330.39 | C5: =+$N$5/12*C2 -> 808660.78 | D5: =+$N$5/12*D2 -> 1212991.2 | E5: =+$N$5/12*E2 -> 1617321.6 | F5: =+$N$5/12*F2 -> 2021651.9 | G5: =+$N$5/12*G2 -> 2425982.3 | H5: =+$N$5/12*H2 -> 2830312.7 | I5: =+$N$5/12*I2 -> 3234643.1 | ... M5: =+$N$5/12*M2 -> 4851964.7 | N5: 4851964.7 | O5: 4851964.7 | P5: =N5/O5 -> 1
A6: Hijos | B6: =+$N$6/12*B2 -> 203905.29 | C6: =+$N$6/12*C2 -> 407810.58 | D6: =+$N$6/12*D2 -> 611715.87 | E6: =+$N$6/12*E2 -> 815621.16 | F6: =+$N$6/12*F2 -> 1019526.5 | G6: =+$N$6/12*G2 -> 1223431.7 | H6: =+$N$6/12*H2 -> 1427337 | I6: =+$N$6/12*I2 -> 1631242.3 | ... M6: =+$N$6/12*M2 -> 2446863.5 | N6: 2446863.5 | O6: 2000447.9 | P6: =1-P5 -> 0
A7: Serv Doméstico | B7: =+$N$7/12*B2 -> 257586.25 | C7: =+$N$7/12*C2 -> 515172.5 | D7: =+$N$7/12*D2 -> 772758.75 | E7: =+$N$7/12*E2 -> 1030345 | F7: =+$N$7/12*F2 -> 1287931.2 | G7: =+$N$7/12*G2 -> 1545517.5 | H7: =+$N$7/12*H2 -> 1803103.8 | I7: =+$N$7/12*I2 -> 2060690 | J7: 2318276.2 | K7: 2575862.5 | L7: =+$N$7/12*L2 -> 2833448.8 | M7: =+$N$7/12*M2 -> 3091035 | N7: 3091035
A8: Primas de Seguro | B8: =+$N$8/12*B2 -> 13896.5 | C8: =+$N$8/12*C2 -> 27793 | D8: =+$N$8/12*D2 -> 41689.5 | E8: =+$N$8/12*E2 -> 55586 | F8: =+$N$8/12*F2 -> 69482.5 | G8: =+$N$8/12*G2 -> 83379 | H8: =+$N$8/12*H2 -> 97275.5 | I8: =+$N$8/12*I2 -> 111172 | J8: 125068.5 | K8: 138965 | L8: =+$N$8/12*L2 -> 152861.5 | M8: =+$N$8/12*M2 -> 166758 | N8: 166758
A9: Gastos Educación | B9: =+$N$9/12*B2 -> 103034.5 | C9: =+$N$9/12*C2 -> 206069 | D9: =+$N$9/12*D2 -> 309103.5 | E9: =+$N$9/12*E2 -> 412138 | F9: =+$N$9/12*F2 -> 515172.5 | G9: =+$N$9/12*G2 -> 618207 | H9: =+$N$9/12*H2 -> 721241.5 | I9: =+$N$9/12*I2 -> 824276 | J9: 927310.5 | K9: 1030345 | L9: =+$N$9/12*L2 -> 1133379.5 | M9: =+$N$9/12*M2 -> 1236414 | N9: 1236414
L10: =SUM(L3:L6) -> 34081009
L11: =L10/12 -> 2840084.1
B12: Prima Seguro | C12: Gastos | D12: Intereses | E12: Serv Doméstico | F12: Educación
A13: Mes | C13: Sepelio | D13: Hipotecarios
A14: 1 | B14: 83.01 | C14: 83.01 | D14: 1666.67 | E14: =+$N$7/12*A14 -> 257586.25 | F14: =+$N$9/12*A14 -> 103034.5
A15: 2 | B15: 166.02 | C15: 166.02 | D15: 3333.33 | E15: =+$N$7/12*A15 -> 515172.5 | F15: =+$N$9/12*A15 -> 206069
A16: 3 | B16: 249.03 | C16: 249.03 | D16: 5000 | E16: =+$N$7/12*A16 -> 772758.75 | F16: =+$N$9/12*A16 -> 309103.5
A17: 4 | B17: 332.04 | C17: 332.04 | D17: 6666.67 | E17: =+$N$7/12*A17 -> 1030345 | F17: =+$N$9/12*A17 -> 412138
A18: 5 | B18: 415.05 | C18: 415.05 | D18: 8333.33 | E18: =+$N$7/12*A18 -> 1287931.2 | F18: =+$N$9/12*A18 -> 515172.5
A19: 6 | B19: 498.06 | C19: 498.06 | D19: 10000 | E19: =+$N$7/12*A19 -> 1545517.5 | F19: =+$N$9/12*A19 -> 618207
A20: 7 | B20: 581.07 | C20: 581.07 | D20: 11666.67 | E20: =+$N$7/12*A20 -> 1803103.8 | F20: =+$N$9/12*A20 -> 721241.5
A21: 8 | B21: 664.08 | C21: 664.08 | D21: 13333.33 | E21: =+$N$7/12*A21 -> 2060690 | F21: =+$N$9/12*A21 -> 824276
A22: 9 | B22: 747.09 | C22: 747.09 | D22: 15000 | E22: =+$N$7/12*A22 -> 2318276.2 | F22: =+$N$9/12*A22 -> 927310.5
A23: 10 | B23: 830.1 | C23: 830.1 | D23: 16666.67 | E23: =+$N$7/12*A23 -> 2575862.5 | F23: =+$N$9/12*A23 -> 1030345
A24: 11 | B24: 913.11 | C24: 913.11 | D24: 18333.33 | E24: =+$N$7/12*A24 -> 2833448.8 | F24: =+$N$9/12*A24 -> 1133379.5
A25: 12 | B25: 996.12 | C25: 996.12 | D25: 20000 | E25: =+$N$7/12*A25 -> 3091035 | F25: =+$N$9/12*A25 -> 1236414
